Workbook

Sheet Temenos

Sheet Home
B2: Process Area | D2: Summary | E2: No of Processes
C3: Customer Relationship Management Processes | D3: CRM processes consist of customer on-boarding and associated processes such as KYC, AML and Campaign & Contact Management. It also includes Call Centre processes. | E3: =' (0) Customer Relationship Mgmt'!G3 -> 59 | G3: Note : Processes with Asterisk (*), are being used in more than one Vertical as Shortcut.
C4: Retail Banking Processes | D4: Retail Banking processes cover a range of service offerings such as Savings & Current Accounts, Deposits, Consumer Loans, Mortgages, Teller Transactions - including Cash, Currency Exchange, Travellers Cheques etc. Complete end-to-end processing is supported, from account opening/ loan origination, establishing lending arrangement, setting up of sweeps/ standing orders, and account/contract maintenance and closure. | E4: ='(1) Retail Banking Processes'!G3 -> 166
C5: Corporate Banking Processes | D5: Corporate Banking processes support Corporate Current and Deposit Accounts, Corporate Loans, Project Loans, Syndicated Lending, Correspondent Banking, Trade Finance & Guarantees, Factoring & Forfaiting Processes and Supply Chain Finance. | E5: ='(2) Corporate Banking Processes'!G3 -> 238
C6: Transactional Processes | D6: Transactional processes consist of Payments and Cheque Processing/ Clearing. These are normally performed at Back office as they are of high volume and operationally intensive in nature. | E6: ='(3) Transactional Processes'!G3 -> 496
C7: Treasury Processes | D7: Treasury processes support a range of vanilla (FX, MM) as well as Derivative products (FRAs, SWAPS, CCY Swaps etc). Customer position analysis, formulation of trading strategy, trade initiation, execution and settlement etc. are covered. | E7: ='(4) Treasury Processes'!G3 -> 79
C8: Private Wealth Management Processes | D8: Private Wealth Management processes covers the full life cycle of discretionary wealth management - from Asset Allocation & Portfolio Modeling, through Client Profiling, Maintenance/Review of portfolios, performance measurement and portfolio rebalancing. This process area also covers a range of processes related to Trading of Securities, Derivatives, Forex and Structured Products, as well as Mutual Funds, Fiduciary placements and administration processes such as Corporate Actions. | E8: ='(5) Private Wealth Management'!G3 -> 319
C9: Online Channels Processes | D9: Online Channels processes covers user set up and maintenance associated with Personal, Corporate and Wealth Management customers. It also includes processes specific to Retail, Corporate and Wealth Management as well as Transactional online channels processes. | E9: ='(6) Online Channels'!G3 -> 116
C10: Security Management (SMS) Processes | D10: Security Management System (SMS) processes include setting up and maintenance of users and user related parameters in the system. | E10: ='(7) Security Management (SMS)'!G3 -> 5
C11: Financial Accounting Parameter Processes | D11: Processes for maintaining parameters relating to financial accounting, accounting rules, set up of general ledger and financial reporting. | E11: ='(8) Financial Accounting'!G3 -> 34
C12: Core Parameter Processes | D12: Processes for setting up basic Transact parameters such as Interest, Fees and Tax related parameters. | E12: ='(9) Core Parameters'!G3 -> 9
C13: Islamic Banking Processes | D13: Islamic Banking Processes cover the work flow of Islamic model such as Asset Request, Approval and Purchase of Islamic Assets. Further it covers the end-to-end processing of Asset / Commodity Sale under different products such as Fixed Profit, Variable Profit and Multi Structured. Also it covers the work flow of Vendor / Supplier Payment. | E13: ='(10) Islamic Banking'!G3 -> 134
C14: Regionalized Solution Processes | D14: Regionalized Solution Processes cater to features that are specific to a particular country/ region. United Kingdom specific processes cover Customer Relationship Management, Financial Services Compensation Scheme (FSCS), Continuity of Access (COA), CRS, BACS Clearing, Clear Bank Interface and ISA / JISA accounts/ deposits service offerings. The United States specific processes cover Customer Relationship Management, Retail and Corporate service offerings. India specific processes cover Corporate service offerings. Australia specific processes cover Retail and Open banking service offerings. Peru specific processes cover Retail and Corporate service offerings. Argentina specific processes cover Retail and Corporate service offerings. Columbia specific processes cover Retail service offerings. Mexico specific processes cover Retail and Corporate service offerings. Hong Kong specific processes cover Retail service offerings. New Zealand specific processes cover Retail service offerings. Global specific processes to cover Retail and Corporate service offerings | E14: ='(11) Regionalized Solution'!G3 -> 268
C15: Digital Engagement Processes | D15: Digital Engagement processes caters to designing, planning and executing results-driven communications (Campaigns) across a variety of Online Channels (Internet and Mobile Banking) and Offline Channels (Email, Secure Message, SMS). Managing real time communication with Customers through Digital Channels is achieved through Digital Engagement User Agents Interfaces (front end applications - Campaign Management User Agent Interface and Campaign Administration User Agent Interface) | E15: ='(12) Digital Engagement'!G3 -> 22
C16: Regulatory Reporting and Compliance Processes | D16: Regulatory Reporting Processes cover the creation of FATCA/ CRS report setup, creation, generation and checking of reports. It also caters to customer personal data definition, searching and protection. Processes involved in loan management and restructuring have also been included. | E16: ='(13) Reporting and Compliance'!G3 -> 66
C17: Financial Crime Mitigation Processes | D17: Financial Crime Mitigation Processes covers the creation of Mandator and User for application and data restrictions. It also caters to creation of Customer on-boarding/ Enhanced due diligence form and creation of Risk Matrix for classification of risk. Knowledge Management allows user to create, generate and manage reports, schedule them and represent the generate reports as dashboards. | E17: ='(14) Financial Crime Mitigation'!G3 -> 74
C18: Fund Accounting Processes | D18: Fund Accounting Processes cover creation of Accounting Chart along with account definitions, structures, and transaction links. This structure is used as a basis for reporting and to produce financial statements. | E18: ='(15) Fund Accounting Processes'!G3 -> 69
C19: Temenos Digital Processes | D19: Temenos Digital Processes covers customer on-boarding , retail and corporate services such as managing account , beneficiary, cheques, lending etc. | E19: ='(16) Digital Banking (Infinity)'!G3 -> 46
C20: Temenos Banking Solution (TBS) Processes | D20: Temenos Banking Solution (TBS) Processes Retail Lending Fulfillment Service (RFS) covers the creation, disbursement, and repayment of Loans. Retail Deposits Banking Service (RDBS) covers the opening & closing of Accounts, Term Deposits, Transferring funds, maintenance, closure of the Accounts/ Term Deposits, Alerts, Multi-Currency Accounts and Multi-Company Groups. Target Instant Payment System (TIPS) Service covers outward remittance, inward credit transfers, and the cancellation of payments. Temenos Enterprise Pricing (TEP) covers Creating package arrangements for pricing benefits, closing the package, updating negotiated price and capturing relationships for relationship pricing. Buy Now Pay Later (BNPL) covers financing options for their retail customers, from Customer registration, Loan creation to Loan cancellation and refund. It also supports the amendment and closure of Facilities and loans. | E20: ='(17) Temenos Banking Solution'!G3 -> 75
C21: Business Banking Processes | D21: Business Banking processes cover a range of service offerings such as Accounts, Deposits, Loans, Asset Finance products that serve the needs of the Small Medium Enterprise (SME) segment. | E21: ='(18) Business Banking Processes'!G3 -> 34
C22: Enterprise Services Processes | D22: Enterprise Services Processes Retail Enterprise Services (RES) covers the opening and closing of Accounts, Term Deposits, Transferring funds, maintenance, closure of the Accounts/ Term Deposits, Multi-Currency Accounts and lending with payment capabilities. Business and Corporate Enterprise Service (BCES) covers the opening and closing of Accounts, Term Deposits, Transferring funds, maintenance, Payments, closure of the Accounts/ Term Deposits, Cash Management, Trade Finance & Guarantees and lending. | E22: ='(19) Enterprise Services'!G3 -> 157
C23: Financial Risk Management Processes | D23: Financial Risk Management illustrates various approaches or methodologies for risk management using reporting tools and techniques. | E23: ='(20) Financial Risk (FRM) '!G3 -> 19
C24: Platform Based Approach Processes | D24: The platform-based approach processes provides a comprehensive and detailed understanding of user journeys within Transact - Core Banking, Payments, Loans, Wealth, Corporate, Trade Finance, Treasury, Financial Crime Mitigation, Cash Management packages. | E24: ='(21) Platform Based Approach'!G3 -> 275
E25: =SUM(E3:E24) -> 2760

Sheet  (0) Customer Relationship Mgmt
D2: Business Area | E2: Customer Relationship Management | G2: In Scope
D3: Total no of processes | E3: =COUNTIF(E8:E79,"*") -> 59 | G3: =COUNTIF(G8:G79,"Yes") -> 59
D4: Release | E4: R25 Model Bank
G6: Scoping
B7: Process Area | C7: Scenario | D7: Process | E7: Process Description | G7: In Scope
B8: Customer Relationship Management Processes
C9: 0.1 Retail Banking Clients | G9: =COUNTIF(G10:G11,"Yes") -> 2
D10: Create Retail Customer (PW) | E10: This process describes the activities for Customer creation, using a PW Process. Process is initiated from the home page. | G10: Yes
D11: Manage Customer Engagements (Retail) | E11: Front Office user checks on the customer's request and validate his existence in the system. New customers will be recorded as prospects before continuing with AML and KYC check. Existing customer's records will be checked for cross-selling opportunities and verified if background checks or record updates are required. The Customer on boarding feature enables the user to choose the activity to be performed based on the status of the prospect/ Customer (existing or new). | G11: Yes
C12: 0.2 Corporate Banking Clients | G12: =COUNTIF(G13:G20,"Yes") -> 8
D13: Amend Customer Charge (Corporate) | E13: This process is used to amend Customer charge. | G13: Yes
D14: Amend Customer Details (Corporate) | E14: This process carries out requests to amend customer related data viz., change customer details or add/ remove additional addresses as well change of the customer status. | G14: Yes
D15: Complete KYC Check (Corporate) | E15: KYC documents are obtained from the customer and checked against a KYC Checklist. For missing documents follow up actions are captured. | G15: Yes
D16: Create Customer Record (Corporate) | E16: Once the required background checks are completed, the user creates/ updates the customer record. All inputs in the system will be approved by a Supervisor. Subsequently, scanned documents are attached to the customer record. This process is repeated for all associated entities. | G16: Yes
D17: Manage Customer Engagements (Corporate) | E17: This process begins when the Relationship Manager obtains all required documents from the customer. New customers will be recorded as prospects, before continuing with AML and KYC checks. In case of existing customers, checks are made to see if any KYC/AML updates are required. The Customer onboarding feature enables the user to choose the activity to be performed based on the status of the prospect/ Customer (existing or new). | G17: Yes
D18: Perform AML Check (Corporate) | E18: This process deals with carrying out AML Blacklist checks on databases like OFAC (Office of Foreign Assets Control) or PEP (Politically Exposed Persons). The results from such checks are captured in the customer record. | G18: Yes
D19: Set or Remove Posting Restrict (Corporate) | E19: This process covers executing a Customer's request or an external/ internal request for setting/removing restrictions for posting. The restriction can be set either at the Customer level or at an account level. | G19: Yes
D20: Set Up Mandates and Signatory Groups | E20: The process depicts the set up of signatory groups and mandates. Customer is attached to respective signatory group. Mandate Application group is formed by logically grouping Transact applications/ versions. The mandate requirement can be defined for customer, account or portfolio and in turn linked to the appropriate application group and mandates. | G20: Yes
C21: 0.3 Private Wealth Management Clients | G21: =COUNTIF(G23:G34,"Yes") -> 10
D22: 0.3.1 Customer Creation
D23: Create Customer Record (PWM) | E23: This process describes the activities for Customer creation, using a PW Process. Once the required background checks are completed, the user creates/ updates the Customer record. Subsequently, scanned documents are attached to the customer record. This process is repeated for all associated entities. | G23: Yes
D24: Generate Documents For Suggested Investment Strategies | E24: Once an investment strategy is defined, the Relationship Manager will generate all required documents, including model portfolios and a confirmation is sought from the client. | G24: Yes
D25: Manage Customer Engagements (PWM) | E25: Relationship Managers will initiate a client on-boarding process where they capture prospect data. This data is subsequently validated by the supervisor. Once approved the RM will complete the prospect record and initiate the required background checks. If the prospect or customer already exists, a handover is performed. | G25: Yes
D26: Perform AML or KYC Check (PWM) | E26: KYC documents are obtained from the customer and checked against a KYC Checklist. For missing documents follow up actions are captured. | G26: Yes
D27: Perform Customer Risk Profiling | E27: Once all required background checks are completed the investment representative will perform MiFID risk profiling, wherever applicable, and investment risk profiling for the client in order to generate an investment proposal. | G27: Yes
D28: 0.3.2 Portfolio Opening
D29: Build Portfolio | E29: Once the Customer portfolio is created, a further request can be placed to create a new portfolio of securities. Customer confirms the amount for which this portfolio needs to be built. Based on the amount and investment strategy, bank provides a basket of possible securities for Customer's portfolio. Once the basket of suggested securities is approved by the Customer, this portfolio is used by the bank to initiate and execute trade orders. | G29: Yes
D30: Open Customer Portfolio | E30: After a Customer record is created in the system, the Customer portfolio is set up with required restrictions. The assets are subsequently transferred into Customer's account. If Customer requests for building portfolio, the portfolio is built based on the amount committed and strategy selected by the Customer. | G30: Yes
D31: Set Block and Restrictions | E31: Investment Representative decides on the type of restrictions to be set (Holding/ Transaction restriction) by inputting the appropriate portfolio restrictions. | G31: Yes
D32: Set PWM Alerts | E32: After the Customer portfolio is created and authenticated, Customer alert preferences are captured in the system. Based on this setup and occurrence if the event(s), Customer is sent appropriate alerts through the selected delivery channels. | G32: Yes
D33: 0.3.3 Portfolio Closing
D34: Close Customer Portfolio | E34: Request for closure triggers a series of actions viz., marking of closure in customer's portfolio, collection of fees/ charges and transfer of assets from the client's account. | G34: Yes
C35: 0.4 Islamic Banking Clients | G35: =COUNTIF(G36:G37,"Yes") -> 2
D36: Create Customer (Islamic) | E36: This process describes the activities involved in Customer creation, once the required background checks are completed, the user creates/ updates the customer record. AML and KYC checks are done and documents received from customer are scanned and attached to the customer record. | G36: Yes
D37: Manage Customer Engagements (Islamic) | E37: This process begins with Front Office user checking on the customer's request and validating if the customer is already registered in the system. New customers will be recorded as prospects before continuing with AML and KYC check. Existing customer's records will be checked for cross-selling opportunities and verified if background checks or record updates are required. | G37: Yes
C38: 0.5 Financial Institutions | G38: =COUNTIF(G39:G45,"Yes") -> 7
D39: Amend Routing Instructions | E39: New settlement instructions need to be verified, approved and updated in the system. | G39: Yes
D40: Create Bank Customer | E40: This process deals with the creation of a Bank Customer record in the system. | G40: Yes
D41: Create Routing Instructions | E41: Once a record for a Financial Institution is created and settlement instructions obtained, routing instructions are captured in the system. | G41: Yes
D42: Generate or View Statement MT942 | E42: Based on the parameter setting, MT942 can be generated for the transactions processed in the account. This may contain transactions happened during the day or from the last statement generated time, or can be filtered based on the amount of transaction, as per setup. | G42: Yes
...

Sheet (1) Retail Banking Processes
D2: Business Area | E2: Retail Banking | G2: In Scope
D3: Total no. of processes | E3: =COUNTIF(E8:E215,"*") -> 166 | G3: =COUNTIF(G8:G215,"Yes") -> 166
D4: Release | E4: =' (0) Customer Relationship Mgmt'!E4 -> R25 Model Bank
G6: Scoping
B7: Process Area | C7: Scenario | D7: Process | G7: In Scope
B8: Retail Banking Processes
C9: 1.1 Account and Deposit Processes | G9: =COUNTIF(G10:G61,"Yes") -> 48
D10: 1.1.1 Accounts and Deposits
D11: Create Arrangement Account | E11: This Process depicts receipt of an arrangement (AR) account opening form from the customer along with an initial deposit. Successful opening of the AR account leads to associated sub processes viz., issue of debit card, cheque book issue, set up standing instruction/ sweep, set up overdraft limit etc. | G11: Yes
D12: Create Limit Arrangement Account | E12: This Process depicts creation of a Limit Arrangement account for the purpose of calculating charges on Limit balances. Limit Arrangement created, needs be attached as Charge Account in the Limit set for the customer's Current Account Arrangement. | G12: Yes
D13: Create Product Bundle | E13: The process details out the tasks involved in the bundling various products like Off set mortgage, interest compensation, interest upgrade, bonus interest, pooling of accounts etc. | G13: Yes
D14: Issue Cheque Book | E14: This process describes issue of cheque book to the customer either as a part of account opening process or on receipt of an ad hoc request. | G14: Yes
D15: Issue Debit Card | E15: This process describes Debit card issue as part of account opening or on receipt of an adhoc request. | G15: Yes
D16: Issue Passbook | E16: The process relates to issuance of a passbook to a new Customer or to an existing Customer on a specific request. | G16: Yes
D17: Open Deposit (AA) | E17: This process describes activities involved in the creation and funding of a fixed deposit/ bond (Fixed/ Floating/ Short term/ Long term etc.). Deposit funding can be through fund transfer, cash or using payment order based on captured beneficiary details | G17: Yes
D18: Open Discounted Deposit (AA) | E18: This process describes creation and funding of a discounted (interest paid in advance) fixed deposit/ bond (Fixed/ Floating/ Short term/ Long term etc.) through "AA" module. | G18: Yes
D19: Open Safe Deposit Box (SDB) | E19: This process describes creation and funding of a Safe Deposit Box through the "AA" module. | G19: Yes
D20: 1.1.2 Account or Deposit Administration
D21: Amend Arrangement Account | E21: This process describes the receipt of an amendment request for an arrangement account from the Customer and capturing the amendments in the system. The amendment can also be bank initiated. Amendments related to change product/ account details/ holding pattern or to set dormancy/ posting restrict or to renegotiate arrangement/ adjust balances and bills of an arrangement account is done through new activity option in AA overview. | G21: Yes
D22: Amend Deposit (AA) | E22: This process describes the activities involved in the amendment of a deposit based on a Customer request. | G22: Yes
D23: Amend Product Bundle | E23: The process details out the tasks involved in amending the product bundle created for a Customer. | G23: Yes
D24: Block or Unblock Funds | E24: This Process describes blocking and unblocking of funds for an account, for a specific period and amount. | G24: Yes
D25: Cancel Account Sweep | E25: This process describes the cancellation of sweep set up for an account. | G25: Yes
D26: Change Interest and Payment Schedule (AA) | E26: This process describes how to change Debit/ Credit Interest and Interest Payment Frequency (Payment Schedule) for an Arrangement Account. | G26: Yes
D27: Change Primary Customer (AA) | E27: This process describes how to change a Primary Customer for an Arrangement Account. | G27: Yes
D28: Close Arrangement Account (AA) | E28: The process describes the activities involved in the closure of an arrangement account. Customer request is received along with the unused deliverables (chequebook, debit card, etc.). The details are captured in the system and the closure activities are completed. Account closure can be settled either through cash, account transfer, or payment order. | G28: Yes
D29: Close Safe Deposit Box (SDB) | E29: The process begins with the receipt of an Safe Deposit Box arrangement closure request along with the deliverables (Keys etc.). The details are captured in the system and the closure activities are completed. The user has an option to pay the Safe Deposit Box arrangement closure proceeds in three modes, namely account transfer, teller and funds transfer. | G29: Yes
D30: Generate Account Statements | E30: This process describes handling of a customer request for an account statement (Current period/ Past period /Ad-hoc). | G30: Yes
D31: Generate Deposit Advices | E31: This process describes generation of an ad hoc deposit advice (AA). | G31: Yes
D32: Generate MT112 - Status of Request for Stop Payment of a Cheque | E32: This Process is to generate MT112 - which is sent by the drawee bank (on which a cheque is drawn) to the drawer bank or the bank acting on behalf of the drawer bank with the details of action that have been taken while stop payment of a cheque as referred in the Message. | G32: Yes
... D54: Process Incoming Statement Request | E54: This process describes the activities involved in receiving statement requests as incoming MT920. Corresponding statement response is generated either through STP (Straight Through Process) or COB (Closure of Business) as per the frequency set up in ACCOUNT.STATEMENT application. Based on the statement request, an outward statement response (MT940, 941, 942 & 950) is generated. | G54: Yes
D55: 1.1.3 Product Administration
D56: Create Product * | E56: This process describes the activities for setting up a product under the hierarchy of a product group. The product conditions are created or existing conditions are re-used and linked to a property. Subsequently the product set up is validated (proofed) and published, i.e., the product is now available for users to start creating arrangement(s). The same process can be used for amending the product also. | G56: Yes
D57: Create Product Group * | E57: This process describes the activities for setting up a product group under a product line. The Product Build set up under Arrangement Architecture is hierarchical and allows the derivation of product structures from higher levels. For example, a Product (e.g. 15 year Fixed Rate Mortgage) will be derived from a Product Group (e.g. Mortgages), which will be derived from a Product Line (e.g. Lending). In addition to this structural hierarchy, the Product Builder enables the definition of “families” of products through Product Inheritance. The purpose of a Product Group is to provide a structure and constraints to any product derived from the group. The same process can be used for amending the product group. | G57: Yes
D58: 1.1.4 Retail PW Processes
D59: Add Joint Holder To Account (PW) | E59: This process indicates the activities of a Branch User, to add a joint holder to an existing account. | G59: Yes
D60: Issue Cheque Book And Debit Card (PW) | E60: The process describes the activity of capturing cheque book issue details and debit card issue details. | G60: Yes
D61: Open Account (PW) | E61: The process describes various steps involved in account opening and account related services like capturing debit card details. | G61: Yes
C62: 1.2 Teller Processes | G62: =COUNTIF(G64:G118,"Yes") -> 40
D63: 1.2.0 Teller Financial Services
...

Sheet (2) Corporate Banking Processes
D2: Business Area | E2: Corporate Banking | G2: In Scope
D3: Total no. of processes | E3: =COUNTIF(E8:E299,"*") -> 238 | G3: =COUNTIF(G8:G299,"Yes") -> 238
D4: Release | E4: ='(1) Retail Banking Processes'!E4 -> R25 Model Bank
G6: Scoping
B7: Process Area | C7: Scenario | D7: Process | E7: Process Description | G7: In Scope
B8: Corporate Banking Processes
C9: 2.1 Accounts and Deposits | G9: =COUNTIF(G11:G74,"Yes") -> 56
D10: 2.1.1 Current Account
D11: Complete Corporate Current Account Opening | E11: This process relates to handing over current account deliverables (cheque book, debit card etc.) to the customer. The signatories and mandate of the Customer(s) is/ are captured as part of this process. | G11: Yes
D12: Create Current Account Arrangement (Corporate) | E12: The process describes the steps associated with creation of corporate current account arrangement (AR). After successful authorization, the account opening is done which leads to other processes viz., verify external cheque, account to account transfer etc. | G12: Yes
D13: Issue Cheque Book (Corporate) | E13: This process describes the issue of cheque book to the Corporate customer, either as a part of the account opening process or on receipt of an ad hoc request. | G13: Yes
D14: Issue Debit Card (Corporate) | E14: This process describes the issue of Debit Card either as a part of the account opening process or on receipt of an ad hoc request. | G14: Yes
D15: Manage Account Conditions (Corporate) | E15: The process describes the activities related to the maintenance of account specific conditions. | G15: Yes
D16: Manage Account To Account Transfer (Corporate) | E16: The process describes the requests received from Customers at the front office for account to account transfers within the bank. The transactions are performed by the teller after making the necessary checks and authentications. | G16: Yes
D17: Manage Mandates (Corporate) | E17: This process describes the activities involved in capturing signatory group, mandates, mandate application group and attaching them to mandate requirements. Validations are performed against the mandate when a transaction is executed for respective customer, account or portfolio. | G17: Yes
D18: Open Current Account - PW (Corporate) | E18: This process describes the opening of a current account (incl. mandates and issuing of a cheque book), using a PW process. | G18: Yes
D19: Open Current Account (Corporate) | E19: The process describes the steps associated with the opening of a Corporate Current account. Successful authorisation of account opening leads to other processes viz., image capture, initial deposit, issue of cheque book, set up Overdraft limit etc. | G19: Yes
D20: 2.1.2 Deposits
D21: Open Contract Based Deposit - PW (Corporate) | E21: This process describes creation of a "Contract" based fixed deposit (Fixed/ Floating/ Discounted etc.) through the "LD module" using PW. | G21: Yes
D22: Open Contract Based Deposit (Corporate) | E22: This process describes creation of a "Contract" based fixed deposit (Fixed/ Floating/ Discounted etc.) through the "LD module". | G22: Yes
D23: 2.1.3 Cash Management
D24: Cancel Account Sweep (Corporate) | E24: This process describes the cancellation of sweep set up for an account. | G24: Yes
D25: Create External Arrangement Account | E25: This Process describes the creation of an External Arrangement account for the purpose of external Sweeps. Arrangement accounts are set up with linked account number, which will be nostro accounts (beneficiary). The purpose of the external Arrangement account is to act as a Link Account in the Cash pool record in-order to facilitate sweep of funds from the source account to an external account via payment order. | G25: Yes
D26: Create Investment Arrangement Account | E26: This Process describes the creation of an Investment account for the purpose of Investment Sweeps. The Investment products are created with the principal balance as memo balance and other balances as real balance. The purpose of Investment account is to enable the customers to sweep their excess funds into an Investment Instrument. | G26: Yes
D27: Create Main Account and Set up Group Hierarchy (Notional Pooling) | E27: This process describes how accounts can be linked into a hierarchical structure of individual groups. Each group consists of a main account to which other (sub accounts) can be linked. | G27: Yes
D28: Create Sub Account (Notional Pooling) | E28: This process describes how each group consists of a main account to which other (sub accounts) can be linked. A main account in one group can be a sub account in another higher-level group. | G28: Yes
D29: Execute Intra-Day Sweep (Transactional Pooling) | E29: This process describes the execution of an intra-day sweep between customer accounts. The customer request is validated before performing an ad-hoc intra-day transfer. While performing intra-day sweep, cash pool suspend period is calculated and sweep is not executed if the day of sweep falls within cash pool suspend period. If float transfer is set to yes in the Group Param level, then on executing Intraday sweep, balances with future exposure dates (float) will be transferred from the sweep account to the main master account prior to executing the actual sweep. Sweep is executed based on the sweep type set in AC.CASH.POOL (Type: Surplus Sweep or Maintenance Sweep or Two-Way Sweep). | G29: Yes
D30: Execute Maintenance Sweep (Transactional Pooling) | E30: This process describes how a Maintenance sweep is performed. Maintenance Sweep is triggered while executing intra-day sweep by comparing the Sweep Account Balance of the cash pool with the Minimum Amount defined in the Cash Pool record. Credit happens to the sweep account considering the other aspects such as Minimum Transfer Credit, Sweep in units defined in the cash pool and Partial Transfer value defined in the Group Param level. Sweep will not happen if it does not meet the defined criteria in the cash pool. In case of multiple link accounts, Deficit in sweep account is swept as per the Link Account sequence defined in Rule Priority. | G30: Yes
D31: Execute Surplus Sweep (Transactional Pooling) | E31: This process describes how a Surplus sweep is performed. Surplus Sweep is triggered while executing intra-day sweep by comparing the Sweep Account Balance of the cash pool with the Maximum amount defined in the Cash Pool record. Debit to the sweep account happens considering the other aspects such as Minimum Transfer Debit, Maximum concentration Amount in link account, Sweep in Units defined in the cash pool and Partial Transfer value defined in the Group Param level. Sweep will not happen if it does not meet the defined criteria in the cash pool. In case of multiple link accounts, Surplus credit is executed as per the Link Account sequence defined in Rule Priority. | G31: Yes
D32: Execute Two Way type Sweep (Transactional Pooling) | E32: This process describes how a Two-Way sweep is performed. Two-Way sweep in general can be either Maintenance Sweep or Surplus sweep depending on the Sweep Account balance and Minimum/Maximum amount defined in the Cash Pool record. This process follows the same flow as defined in Maintenance/ Surplus Sweep once the Sweep type is identified. Sweep will not happen if it does not meet the defined criteria in the cash pool. For Two way sweep type, maintenance sweep condition is checked first and then the surplus sweep condition is checked. In case of multiple link accounts, Deficit in sweep account is swept as per the Link Account sequence defined in Rule Priority while Return Rule Priority sequence is considered for Surplus credit to Link Account. | G32: Yes
D33: Remove Sub Account from Notional Pooling | E33: This process describes how to remove a sub account from the group any time. | G33: Yes
D34: Reverse a Sweep Transaction (Transactional Pooling) | E34: This process describes the activities for revoking a sweep transaction already executed by the system. Reversal entries are passed during close of business. | G34: Yes
D35: Set Up or Amend Pool and Groups (Transactional Pooling) | E35: The group is created by specifying the master account. To the created group multiple accounts are linked to create the pool. This creates a tree structure of accounts held by a Corporate. The pooling could be either Shared or a Sweep. In case of Shared Pooling, the sum total of all account balances are checked while performing the transaction. For a Sweep setup, the balances are transferred according to defined rules. Cash Pool can be suspended - For a day by setting Suspend Start Date (or) - For a specific period by setting Suspend Start and Suspend End Date (or) - For an Indefinite period by setting Suspend Start Date and Suspend Indefinitely Sweep will not be performed between the accounts in the Cash Pool during Cash Pool suspension period. | G35: Yes
D36: Set Up Capitalisation Frequency and Credit Interest (Notional Pooling) | E36: This process describes how to setup capitalisation frequency and credit interest for accounts. | G36: Yes
D37: 2.1.4 Balance Netting - Cash Management
D38: 2.1.4.1 Manual Creation of Balance Netting Cash Pool
D39: Create Currency Summary (CS) or Summary Account (SA) | E39: This Process depicts the creation of Summary Account/ Currency Summary accounts which is part of the Cash Pool. Currency Summary account represents the sum of underlying Transaction Accounts of a Specific Currency. Summary Account represents the sum of underlying Transaction Account balances converted to the currency of the Summary Account. | G39: Yes
D40: Create Currency Top Account (CT) | E40: This Process depicts the initial process of Cash Pool i.e., creation of Currency Top Account. Currency Top Account represents the Company's outstanding balances per currency with the bank which is updated real-time with transactions from the Transaction Account in the same currency. Successful opening of the CT Account leads to associated sub processes viz., Creation of Master Account (MA), Currency Summary Account (CS)/ Summary Account(SA), Transaction (TR) Account to form the Cash Pool. | G40: Yes
D41: Create Master Account (MA) | E41: This Process depicts creation of Master Account as part of the Cash Pool. Master Account represents the customers total CT Account balances converted into Master Account currency which is updated real-time when there is an update in CT Account. The CT Account determines the currency of the Master Account and forms the Uppermost level in the Balance Netting Structure. | G41: Yes
D42: Create Transaction Account (TR) | E42: This Process depicts the creation of Transaction Accounts of the Cash Pool. Transaction Account is the Operational Account in the Cash Pool where transactions are booked with Real time transaction and balance updation. This can be denominated in any currency eligible. Relevant MA or SA/CS is mentioned in the creation process to form a complete cash pool. | G42: Yes
...

Sheet (3) Transactional Processes
D2: Business Area | E2: Transactional Processes | G2: In Scope
D3: Total no. of processes | E3: =COUNTIF(E8:E635,"*") -> 496 | G3: =COUNTIF(G8:G636,"Yes") -> 496
D4: Release | E4: ='(2) Corporate Banking Processes'!E4 -> R25 Model Bank
G6: Scoping
B7: Process Area | C7: Scenario | D7: Process | E7: Process Description | G7: In Scope
B8: Transactional Processes
C9: 3.1 Payment Processes | G9: =COUNTIF(G10:G73,"Yes") -> 50
D10: 3.1.1 Drafts (Bankers Cheques)
D11: Manage Receipt Of Draft Stock | E11: This process describes activities performed by a front office Customer Service Officer on receipt of draft inventory from Head Office. | G11: Yes
D12: Perform Draft Encashment | E12: This Process describes the steps involved in settling local currency drafts across the counters by the teller. This can be achieved either by crediting the Customer's account with the bank or settlement by cash. | G12: Yes
D13: Process Cancellation Of Draft | E13: This process describes the steps involved in cancellation of LCY/ FCY draft. Once a confirmation is obtained that the draft is unpaid, for a LCY draft, immediate cancellation can be done, whilst in case of a FCY draft, the same is carried out upon receipt of confirmation of stop payment from the Nostro correspondent, on whom the FCY draft was issued. | G13: Yes
D14: Process Internal Draft Payments | E14: This process describes activities involved in processing internal draft. In an internal draft, the Initiator and Beneficiary will have accounts in the same bank. | G14: Yes
D15: Process Stop Payment Of Draft | E15: This process involves carrying out a stop payment of a draft. In case of a LCY draft, necessary status updates are carried out. For FCY drafts, stop payment confirmation is requested from the correspondent bank and response recorded and acted upon. | G15: Yes
D16: Receive and Process Request Of Stop Payment Of FCY Draft | E16: This process describes the steps involved in receiving and processing MT111 message. MT112 is generated and sent based on the status of the FCY draft. | G16: Yes
D17: Receive Request for Advice of Cheque | E17: This process describes the steps involved in receiving and capturing the details of MT110 (Advice of Cheque) which is used to advice the drawee bank, or confirm to an enquiring bank the details concerning the cheque referred to in the message. | G17: Yes
D18: Receive Request For Cancellation Of Draft | E18: This process deals with Customer giving a request for cancellation of a draft. The front office validates the request and forwards it to the back office for effecting the cancellation. | G18: Yes
D19: Receive Request For Revocation Of Stop Payment Of LCY Draft | E19: The process begins with the receipt of a revocation of stop payment request of a LCY draft. Necessary validations are carried out before forwarding the request to back office for processing. | G19: Yes
D20: Receive Request For Stop Payment Of Draft | E20: This process deals with Customer giving a request for stop payment of a draft. The front office validates the request and forwards it to the back office for effecting the stop payment. | G20: Yes
D21: Receive Request To Issue Draft | E21: The process is initiated on receipt of the draft/ bankers' cheque request by the front office. The request is then forwarded to the back office for further processing. | G21: Yes
D22: Revoke Stop Payment of LCY Draft | E22: This process describes activities associated with revocation of stop payment of a LCY draft. | G22: Yes
... D24: Reconcile Nostro Accounts * | E24: Periodically, Nostro accounts as in Bank's books will need to be reconciled with the account statement sent by the Nostro Bank. The statements may be received via SWIFT or physically and Transact automatically matches items and any unmatched items will need to be investigated. | G24: Yes
D25: 3.1.2 Standing Orders
D26: Cancel Standing Order Instruction | E26: This process describes the activities associated with the cancellation of a standing order instruction on receipt of a request from the customer. | G26: Yes
D27: Execute Standing Order | E27: This process is carried out for execution of the standing order. The payments orders are automatically generated using Standing order details. | G27: Yes
D28: Receive Request For Standing Order | E28: The process begins with the receipt of Standing order request from our Customers. Necessary verification is done before setting up the standing order. | G28: Yes
D29: Set Up Standing Order | E29: In this process, the standing order is set up based on the request of the customer. The request can be various types, viz. fixed amount transfer, maximum balance transfer, bulk standing order etc. | G29: Yes
D30: 3.1.3 Direct Debits
D31: 3.1.3.1 Direct Debits (Inward)
D32: Execute Direct Debit (Inward) | E32: The process describes the execution of the direct debit after a debit file is received from an originating bank. | G32: Yes
D33: Receive and Execute BACS Direct Debit (Inward) | E33: The process describes activities associated with the execution of an Inward Direct Debit. When claim file is received from Clearing, validations are performed. Upon successful validation, claims are honored, funds debited from Customer and accounting/ settlement entries raised. When validations fail, based on parameter setup, transactions are automatically cancelled or manually repaired/ cancelled. | G33: Yes
D34: Receive Request for Direct Debit E-Mandate (Inward) | E34: This process describes activities involved in the management of Direct Debit E-Mandates, which are registered and maintained electronically. Upon successful validation, the bulk file is debulked. Individual transactions are processed based on the request type received (pain.009-Register new mandate, pain.010-Amend existing mandate, pain.011-Cancel existing mandate). Corresponding error code and reason gets updated if validation fails. A response file is sent to centralized mandate system containing status of processed transactions. | G34: Yes
D35: Receive Request For Direct Debit Mandate (Inward) | E35: This process describes the validations that are undertaken on receipt of a customer's request for set up of an inward direct debit mandate. | G35: Yes
D36: Set Up Direct Debit Mandate (Inward) | E36: The process describes activities associated with registering an inward direct debit mandate in the system. | G36: Yes
D37: 3.1.3.2 Direct Debits (Outward)
D38: Cancel Direct Debit Instruction | E38: This process describes the activities associated with the cancellation of a Direct Debit mandate (Inward/ Outward). | G38: Yes
D39: Execute Cancellation of Outward Collection before Distribution to Clearing | E39: This process describes the steps involved in the cancellation of an outward Direct Debit collection request received via camt.055, API, etc. Post validation of the request, the cancellation request is accepted if payment/ collection is not sent to clearing. The cancellation request is rejected if the payment/ collection is already sent to clearing. Appropriate positive/ negative responses are sent via camt.029, pain.002 or API. | G39: Yes
D40: Execute Direct Debit (Outward) | E40: The process describes activities associated with the creation and execution of an outward direct debit mandate. On the claim date, system automatically generates and sends the Claim file to TPH. OFF-US the claim will be sent to clearing and Accounting/Settlement entries will be posted if claim is honored by debtor bank. ON-US Claims will be honored or returned to the customer based on direct debit validation. | G40: Yes
D41: Receive Request For Direct Debit (Outward) | E41: This process describes the validations that are undertaken on receipt of a customer's request for set up of an outward direct debit mandate. | G41: Yes
D42: Set Up Direct Debit Mandate (Outward) | E42: The process describes activities associated with registering an outward direct debit mandate in the system. | G42: Yes
D43: 3.1.4 Direct Credits
...

Sheet (4) Treasury Processes
D2: Business Area | E2: Treasury | G2: In Scope
D3: Total no. of processes | E3: =COUNTIF(E8:E142,"*") -> 79 | G3: =COUNTIF(G8:G142,"Yes") -> 79
D4: Release | E4: ='(3) Transactional Processes'!E4 -> R25 Model Bank
G6: Scoping
B7: Process Area | C7: Scenario | D7: Process | E7: Process Description | G7: In Scope
B8: Treasury Processes
C9: 4.1 Derivatives (Own book) | G9: =COUNTIF(G11:G22,"Yes") -> 9
D10: 4.1.1 Position and Market Analysis
D11: Perform Position and Market Analysis (Derivatives or Own Book) | E11: As part of this process, current position and market information is analysed and an appropriate trading strategy for derivatives (own book) is formulated. | G11: Yes
D12: 4.1.2 Trade Initiation
D13: Execute Trade (Derivatives or Own Book) | E13: This process describes the capture of an Own book or a Customer derivatives deal in the system. In own book it's a direct trade input and for Customers the trade can be originated through an order as well. | G13: Yes
D14: 4.1.3 Settlement
D15: Execute Settlement (Derivatives or Own Book) | E15: Once a Derivatives Trade (Own Book) is completed and verified, system automatically generates accounting entries and Trade confirmation advices. | G15: Yes
D16: 4.1.4 Administration
D17: Create Derivatives Exchange Master * | E17: This process covers the creation of a derivatives exchange master. The details of the exchange/ market like description, address and the margins are captured here. | G17: Yes
D18: Create Derivatives Master * | E18: This process describes the activities involved in creation of a derivatives master for all instruments (futures, stocks or options) that is traded in the exchange. An Asian or non Asian derivative master is created based on option style of the instrument. | G18: Yes
D19: Exercise Option or Assignment (OTC) | E19: The process is triggered over the counter (OTC), when the customer requests for exercising the option or where counterparty requests for an assignment. The option is exercised/ assigned and system creates a closeout record. On committing the closeout record, system creates Forex trade. System can also be parameterised to automatically exercise an Option if pre-defined conditions are met. | G19: Yes
D20: Manage Maturity or Expiry (Derivatives or Own Book) | E20: On maturity of futures contract or expiry of options contract, system would automatically mark the record as 'expire'. This process is for manually capturing the maturity of a futures contract or the expiry of an option contract. | G20: Yes
D21: Perform Closeout (Derivatives or Own Book) | E21: Comparable Buy and Sell Trades can be closed out either manually by specifying selection criteria or automatically by the System (if so parameterised). A close out record is created and upon authorisation, system automatically closes out the positions and generates the accounting entries. | G21: Yes
D22: Trigger Exotic Options (Derivatives or Own Book) | E22: For exotic options, if the Trigger is reached, this has to be manually input in Transact. E.g. for a Knockout option, when the knockout price is reached, Investment representative will have to input that the option is triggered. Once triggered, the option will automatically become live or expire as the case maybe. | G22: Yes
C23: 4.2 Securities (Own book) | G23: =COUNTIF(G25:G37,"Yes") -> 10
D24: 4.2.1 Position and Market Analysis
D25: Perform Position and Market Analysis (SEC or Own Book) | E25: This process describes analysing the position, outstanding orders and market data to formulate trading strategy. | G25: Yes
D26: 4.2.2 Trading Initiation and Execution
D27: Execute Trade (Sec or Own Book) | E27: This process describes execution of a trade (Sec/ Own book). The trade details are captured in the system where automatic validation vis-à-vis validation of trade data for stock and cash availability, restrictions, etc., is carried out. | G27: Yes
D28: Generate Advices and Perform Pre Matching (Sec or Own Book) | E28: The process describes authorising of security trades for proprietary (own book) portfolios. After trade authorisation, system will post accounting entries and advices to Broker & Custodian will be generated. | G28: Yes
D29: 4.2.3 Settlement
D30: Execute Settlement (Sec or Own Book) | E30: This process describes settlement of a trade (Sec/Own book). On trade authorization and once the advices and pre-matching is complete, system automatically checks for the type of settlement to be performed (actual vs contractual). On receipt of appropriate settlement confirmation from the depository/ custodian, trade is “settled” with the updation of cash and security positions. | G30: Yes
D31: Perform Dealer Book Portfolio Transfer | E31: Process describes the transfer of assets between dealer book portfolios. The positions are defined and transfer details are captured/ updated. | G31: Yes
D32: Perform Off-Market Trade or Transfers (Own Book) | E32: This process describes the activities relating to capture of data for off-market transfer in/ out of Proprietary (own book) portfolios. | G32: Yes
D33: 4.2.4 Administration
D34: Create Security Master * | E34: The process describes capturing of new securities into the master for future trading. | G34: Yes
D35: Maintain Security Prices * | E35: The security prices are updated into the tables through external system's interface or manually updated. | G35: Yes
D36: Set Up Broker * | E36: Broker is opened as a Customer in Transact. As part of this process, data relating to securities, Account creation (if required) and settlement instructions are captured. | G36: Yes
D37: Set Up Depository * | E37: Depository or Custodian is opened as a Customer in Transact. As part of this process, data relating to the custodian's Securities, Nostro accounts and SWIFT address are updated. | G37: Yes
C38: 4.3 FRA | G38: =COUNTIF(G39:G47,"Yes") -> 5
D39: 4.3.1 Position and Market Analysis
D40: Perform Position and Market Analysis (FRA) | E40: This process involves formulation of an appropriate FRA deal strategy after analysis of current position and market information. | G40: Yes
D41: 4.3.2 Trading Initiation and Execution
D42: Execute Trade (FRA) | E42: The process describes capturing FRA trade information details and providing trade data to back office for further processing. Details of Legal Entity details with their status and Expiry date is captured in LE.DIRECTORY. The logic to identify transactions that are in scope of MIFID II is defined in LE.ELIGIBILITY.PARAM. System enables the LEI/NCI checks for those qualifying transactions with Override/Error check. Legal Entity ID/ National Client ID is captured while creating OC.CUSTOMER. While executing a Trade, the LEI check is initiated during transaction commit and override/error triggered where LEI or NCI for the parties to the transaction are not available or conditions not being met. | G42: Yes
...

Sheet (5) Private Wealth Management
D2: Business Area | E2: Private Wealth Management | G2: In Scope
D3: Total no. of processes | E3: =COUNTIF(E8:E399,"*") -> 319 | G3: =COUNTIF(G8:G399,"Yes") -> 319
D4: Release | E4: ='(4) Treasury Processes'!E4 -> R25 Model Bank
G6: Scoping
B7: Process Area | C7: Scenario | D7: Process | E7: Process Description | G7: In Scope
B8: Private Wealth Management Processes | C8: 5.1 Asset Management
C9: 5.1.1 Discretionary Asset Management | G9: =COUNTIF(G11:G41,"Yes") -> 22
D10: 5.1.1.1 Investment Policy Definition
D11: Define Asset Allocation | E11: Asset allocation is a term used to refer to how an investor distributes his or her investments among various classes of investment vehicles. This Process describes defining asset allocation based on various parameters like investment strategy, regulatory restrictions etc. | G11: Yes
D12: 5.1.1.2 Constraints and Restrictions Definition
D13: Maintain Security Recommendation | E13: The recommended list of securities is provided by investment analyst. Recommendations can be maintained in Transact and will be considered e.g. for Rebalancing, … | G13: Yes
D14: Perform Pre Trade and Post Trade Restrictions | E14: Process to setup various holding and transaction restrictions from inputs obtained from regulatory or compliance authorities, analysts etc. | G14: Yes
D15: Set Up Global Constraints | E15: Process to set up regulatory and institutional constraints. A Global constraint could be restriction for trades in certain countries, stocks, … | G15: Yes
D16: 5.1.1.3 Portfolio Modeling
D17: Assign Model To Investment Strategy | E17: This process describes the assignment of a portfolio model to an investment strategy. | G17: Yes
D18: Create Dynamic Model | E18: A dynamic model is created for a virtual customer. This model can then be used as the 'model' portfolio for modelling and rebalancing client portfolios. | G18: Yes
D19: Create Model From Portfolio | E19: An investment strategy or Model is created from an existing client Portfolio (or Dynamic Portfolio). The process describes selection of a Portfolio, based on which Strategy is defined. The system will generate the Strategy (Model) which is then linked to the Investment Strategy file and used to rebalance existing portfolios. | G19: Yes
D20: Maintain Cash Model | E20: A Cash Model or Strategy is created. This is linked to the Investment Strategy file which is then used to rebalance the currency positions of existing portfolios. | G20: Yes
D21: Maintain Securities Model | E21: This process describes maintenance of a Securities Model, e.g. pure equity, balanced, etc. This is linked to the Investment Strategy file so that it can be used to rebalance the securities positions of existing portfolios. | G21: Yes
D22: 5.1.1.4 Comparison and Rebalancing
D23: Perform Currency Rebalancing | E23: Selected Portfolios are compared with a pre-defined Currency Strategy. On running the Comparison, system will generate a list of Portfolios that are in deviation. A rebalancing is then run (the system generates Forex spot trades to balance) to bring the currency positions in sync with the Strategy. | G23: Yes
D24: Perform Group Rebalancing | E24: It is possible to set a Strategy at Group Level and rebalance the group as a whole. An Order of Priority in which the Portfolios in the group are to be rebalanced can be set. Tax Portfolios can have their own Strategy and system would rebalance any Tax Portfolios using their individual strategies, and then ensure that the Group is rebalanced overall to align with the Group Strategy. Proposed orders can be accepted or rejected with a Reason. It is also possible to Raise a certain amount of Cash from a Group of Portfolios, while maintaining the Strategy. If a Portfolio is part of a Rebalancing group, it cannot be rebalanced individually. | G24: Yes
D25: Perform Security Rebalancing | E25: Selected Portfolios are compared with a pre-defined Securities Strategy. On running the Comparison, system will generate a list of Portfolios that are in deviation. A rebalancing is then run to bring the Securities Position in sync with the Strategy. | G25: Yes
D26: Perform What-If Scenario Analysis | E26: The portfolios are selected for what-if analysis and simulations are performed on the portfolios. This will help determine the scenarios in which a rebalancing may be required. | G26: Yes
D27: 5.1.1.5 Order Management
D28: Perform Bulk Order - Normal | E28: This process allows manual rebalancing of Securities Positions of Portfolios. Portfolios which satisfy the selection criteria are rebalanced in one go. For securities that can be bought or sold or switched, the system creates a list of proposed orders and upon accepting the same, security orders are created to rebalance the portfolios. | G28: Yes
D29: Perform Bulk Order (Service Run) | E29: Service based Bulk Orders can be generated for Purchase, Sale and Multiple Switching of securities, through services running at the background. Specific selection criteria has to be specified should be based on the PERCENTAGE and NOMINAL fields, which will be executed on the selected Portfolios and generate the Orders. In the orders generated through SERVICE, the customer details will exist as individual transactions and it will be possible to amend the customer nominals in this application. Here, Auto Select field is set to SERVICE, system will generate/re-generate portfolios with suggested nominals to complete the order. The orders thus generated, has to be executed similar to that of normal Sec Open Orders. | G29: Yes
D30: 5.1.1.6 Back value Processing
D31: Perform Back Value Processing | E31: Portfolio Positions will change when there are back valued transactions. This could be a back valued trade or transaction for the portfolio or a back dated Security price change or back dated exchange rate change. System can be parameterised to automatically update Cash or Security positions when back valued transactions occur and recalculate the performance. | G31: Yes
D32: 5.1.1.7 Performance
D33: Maintain Benchmarks For Performance Reporting | E33: Portfolio performances can be compared to a defined Benchmark. To do this, a Benchmark is defined and then linked to a Portfolio. | G33: Yes
D34: Maintain Composites For Performance Reporting | E34: Composite Portfolio Performances can be displayed and reported in Transact. A composite name has to be defined and Portfolios with similar investment strategies can be plugged to the composite. It is possible to define Composites to comply with GIPS standards. | G34: Yes
D35: Maintain Group Of Portfolios | E35: Portfolios that are in some way related to each other, can be grouped in order to study Performance for the group as a whole. These Transact functions do not require an authorisation. | G35: Yes
D36: 5.1.1.8 Segmentation
D37: Define Portfolio Segmentation | E37: Portfolio Valuation can be viewed as a break-up of different segments. Segments need to be defined and while viewing the valuation, a segment ID can be given to display the details accordingly. | G37: Yes
D38: 5.1.1.9 Hierarchical valuation
D39: Set Up Asset Structures | E39: Portfolio valuation can be viewed in different ways by setting up suitable Hierarchy structures and using them while launching the valuation enquiries. | G39: Yes
D40: 5.1.1.10 Sweep
D41: Execute Sweep (Asset Management) | E41: This process depicts the various ways in which the funds available in the form of securities, shares, positions, accounts, etc. are swept and credited to the customer. | G41: Yes
C42: 5.2 Trading
...

Sheet (6) Online Channels
D2: Business Area | E2: Online Channels Processes | G2: In Scope
D3: Total no. of processes | E3: =COUNTIF(E8:E133,"*") -> 116 | G3: =COUNTIF(G8:G133,"Yes") -> 116
D4: Release | E4: ='(5) Private Wealth Management'!E4 -> R25 Model Bank
G6: Scoping
B7: Process Area | C7: Scenario | D7: Process | E7: Process Description | G7: In Scope
B8: Online Channels Processes
C9: 6.1 User Management - Online Channels Processes | G9: =COUNTIF(G11:G26,"Yes") -> 13
D10: 6.1.1 Initiation
